error: used `panic!()` or assertion in a function that returns `Result`
  --> $DIR/panic_in_result_fn.rs:6:5
   |
LL | /     fn result_with_panic() -> Result<bool, String> // should emit lint
LL | |     {
LL | |         panic!("error");
LL | |     }
   | |_____^
   |
   = help: `panic!()` or assertions should not be used in a function that returns `Result` as `Result` is expected to return an error instead of crashing
note: return Err() instead of panicking
  --> $DIR/panic_in_result_fn.rs:8:9
   |
LL |         panic!("error");
   |         ^^^^^^^^^^^^^^^
   = note: `-D clippy::panic-in-result-fn` implied by `-D warnings`

error: used `panic!()` or assertion in a function that returns `Result`
  --> $DIR/panic_in_result_fn.rs:52:1
   |
LL | / fn function_result_with_panic() -> Result<bool, String> // should emit lint
LL | | {
LL | |     panic!("error");
LL | | }
   | |_^
   |
   = help: `panic!()` or assertions should not be used in a function that returns `Result` as `Result` is expected to return an error instead of crashing
note: return Err() instead of panicking
  --> $DIR/panic_in_result_fn.rs:54:5
   |
LL |     panic!("error");
   |     ^^^^^^^^^^^^^^^

error: aborting due to 2 previous errors

